<?xml version="1.0" ?>
<!-- TODO: https://github.com/aidinrobotics/aidin8_sim/blob/bumsu_camera/urdf/aidin8.urdf-->

<robot name="aidin8">
  <material name="black">
    <color rgba="0.0 0.0 0.0 1.0"/>
  </material>
  <material name="blue">
    <color rgba="0.0 0.0 0.8 1.0"/>
  </material>
  <material name="green">
    <color rgba="0.0 0.8 0.0 1.0"/>
  </material>
  <material name="grey">
    <color rgba="0.2 0.2 0.2 1.0"/>
  </material>
  <material name="silver">
    <color rgba="0.913725490196 0.913725490196 0.847058823529 1.0"/>
  </material>
  <material name="orange">
    <color rgba="1.0 0.423529411765 0.0392156862745 1.0"/>
  </material>
  <material name="brown">
    <color rgba="0.870588235294 0.811764705882 0.764705882353 1.0"/>
  </material>
  <material name="red">
    <color rgba="0.8 0.0 0.0 1.0"/>
  </material>
  <material name="yellow">
    <color rgba="0.8 0.8 0.0 1.0"/>
  </material>
  <material name="white">
    <color rgba="1.0 1.0 1.0 1.0"/>
  </material>

<!--///////////////////// Virtual link for dataset collection /////////////////////-->

  <link name="base1"/>

  <joint name="joint1" type="prismatic">
    <parent link="base1"/>
    <child link="base2"/>
    <origin xyz="0.0 0.0 0.0" rpy="0.0 0.0 0.0"/>
    <axis xyz="0.0 0.0 1.0"/>
    <!-- <limit effort="1000.0" lower="-4" upper="4" velocity="100"/> -->
    <limit velocity="5"/>
  </joint>

  <link name="base2"/>

   <joint name="joint2" type="revolute">
    <parent link="base2"/>
    <child link="body"/>
    <origin xyz="0.0 0.0 0.0" rpy="0.0 0.0 0.0"/>
    <axis xyz="0.0 0.0 1.0"/>
    <limit lower="-3.14" upper="3.14" velocity="0.05"/>
  </joint>
</robot>